Workbook

Sheet README
A1: Formula-Driven Workbook — Trace Guide
A2: HOW TO TRACE | B2: Every computed value is a live formula. Click any cell to see its inputs.
A3: Parameters | B3: Editable yellow cells: SEC by class, EU27 fallback shares, replaceability. Change these and everything recomputes.
A4: Fossil_Shares | B4: Col F: share = Fossil Sum / Total (live). Cols J:K: Country|NACE to share lookup used by Facilities.
A5: Facilities | B5: Col H: SEC via VLOOKUP(class). Col I: fossil share via VLOOKUP(country|nace); falls back to EU27 by NACE if suppressed. Col L: Heat = output × SEC. Col M: Replaceable = Heat × Share × Replace Frac.
A6: Country_Summary | B6: SUMIFS over Facilities filtered to keep=YES. Edit a keep flag or parameter and totals update.
A7: FORMULA CHAIN
A8: Heat Demand | B8: annual_output_t multiplied by SEC (looked up from classification)
A9: Fossil Share | B9: Eurostat country|nace share; if suppressed, EU27 fallback by NACE
A10: Replaceable Heat | B10: Heat Demand multiplied by Fossil Share multiplied by Replaceability Fraction
A11: Country totals | B11: SUMIFS filtered to keep=YES, divided by 1,000,000 to give TWh
A12: FLAGS
A13: keep? = YES/no | B13: Excludes duplicates, closed mills, out-of-EU sites from totals
A14: proxy_capacity = PROXY | B14: Output value shared by 2+ mills = Climate TRACE default, not facility-specific. 35 of 71 kept sites. Verify against company disclosures before trusting site-level results.
A15: FS Source | B15: Eurostat = real country data; EU27 fallback = that country/NACE suppressed
A16: KNOWN LIMITATIONS
A17: Proxy capacity | B17: ~45% of sites share a default output. Largest errors: Nervion (+94%), Saint-Gaudens/Tarascon (+68%). Replace with verified capacity.
A18: Integrated output | B18: Verified NOT double-counted. Setubal, Facture, Figueira match reported paper output.
A19: Tissue SEC | B19: Lowered to 1.5 MWh/t per measured Yankee+hood data.
A20: Totals (current) | B20: 71 kept sites; 20.5 Mt output; 68.3 TWh heat; 15.2 TWh replaceable; 22.3% aggregate fossil share.

Sheet Parameters
A1: PARAMETERS — edit yellow cells to drive all calculations
A3: Thermal SEC by classification (MWh/t)
A4: Classification | B4: SEC (MWh/t)
A5: Pulp | B5: 3.3
A6: Integrated | B6: 5
A7: Paper/Board | B7: 1.3
A8: Tissue | B8: 2.6
A10: EU27 fallback fossil share by NACE
A11: NACE | B11: Fallback share
A12: C17 | B12: 0.2408
A13: C17xP | B13: 0.2686
A14: C1711 | B14: 0.2033
A16: Replaceability fraction
A17: Classification | B17: Replace frac
A18: Pulp | B18: 1
A19: Integrated | B19: 1
A20: Paper/Board | B20: 1
A21: Tissue | B21: 1
A23: Yellow cells are editable. All sheets reference these.

Sheet Fossil_Shares
A1: Eurostat 2023 Fossil Shares (NCV) — components & computed share
A2: Country | B2: Sector | C2: NACE | D2: Total TJ | E2: Fossil Sum TJ | F2: Fossil Share (formula) | G2: Available | H2: Lookup Key | J2: KEY | K2: SHARE
A3: Albania | B3: C17 — All paper & pulp | C3: C17 | E3: 0 | G3: No | H3: =A3&"|"&C3 | J3: =H3 | K3: =IF(ISBLANK(F3),"",F3)
A4: Albania | B4: C17_X_C1711 — Paper excl. pulp | C4: C17xP | E4: 0 | G4: No | H4: =A4&"|"&C4 | J4: =H4 | K4: =IF(ISBLANK(F4),"",F4)
A5: Albania | B5: C1711 — Pulp only | C5: C1711 | E5: 0 | G5: No | H5: =A5&"|"&C5 | J5: =H5 | K5: =IF(ISBLANK(F5),"",F5)
A6: Austria | B6: C17 — All paper & pulp | C6: C17 | D6: 61834.396 | E6: 17366.4 | F6: =E6/D6 | G6: Yes | H6: =A6&"|"&C6 | J6: =H6 | K6: =IF(ISBLANK(F6),"",F6)
A7: Austria | B7: C17_X_C1711 — Paper excl. pulp | C7: C17xP | D7: 9197.39 | E7: 0 | F7: =E7/D7 | G7: Yes | H7: =A7&"|"&C7 | J7: =H7 | K7: =IF(ISBLANK(F7),"",F7)
A8: Austria | B8: C1711 — Pulp only | C8: C1711 | D8: 52637.006 | E8: 17366.4 | F8: =E8/D8 | G8: Yes | H8: =A8&"|"&C8 | J8: =H8 | K8: =IF(ISBLANK(F8),"",F8)
A9: Belgium | B9: C17 — All paper & pulp | C9: C17 | D9: 22562.816 | E9: 883.4 | F9: =E9/D9 | G9: Yes | H9: =A9&"|"&C9 | J9: =H9 | K9: =IF(ISBLANK(F9),"",F9)
A10: Belgium | B10: C17_X_C1711 — Paper excl. pulp | C10: C17xP | E10: 640.2 | G10: No | H10: =A10&"|"&C10 | J10: =H10 | K10: =IF(ISBLANK(F10),"",F10)
A11: Belgium | B11: C1711 — Pulp only | C11: C1711 | E11: 243.2 | G11: No | H11: =A11&"|"&C11 | J11: =H11 | K11: =IF(ISBLANK(F11),"",F11)
A12: Bulgaria | B12: C17 — All paper & pulp | C12: C17 | E12: 914 | G12: No | H12: =A12&"|"&C12 | J12: =H12 | K12: =IF(ISBLANK(F12),"",F12)
A13: Bulgaria | B13: C17_X_C1711 — Paper excl. pulp | C13: C17xP | E13: 11.3 | G13: No | H13: =A13&"|"&C13 | J13: =H13 | K13: =IF(ISBLANK(F13),"",F13)
A14: Bulgaria | B14: C1711 — Pulp only | C14: C1711 | E14: 0 | G14: No | H14: =A14&"|"&C14 | J14: =H14 | K14: =IF(ISBLANK(F14),"",F14)
A15: Croatia | B15: C17 — All paper & pulp | C15: C17 | D15: 1987.634 | E15: 1091 | F15: =E15/D15 | G15: Yes | H15: =A15&"|"&C15 | J15: =H15 | K15: =IF(ISBLANK(F15),"",F15)
A16: Croatia | B16: C17_X_C1711 — Paper excl. pulp | C16: C17xP | D16: 1987.634 | E16: 1091 | F16: =E16/D16 | G16: Yes | H16: =A16&"|"&C16 | J16: =H16 | K16: =IF(ISBLANK(F16),"",F16)
A17: Croatia | B17: C1711 — Pulp only | C17: C1711 | D17: 0 | E17: 0 | G17: Yes | H17: =A17&"|"&C17 | J17: =H17 | K17: =IF(ISBLANK(F17),"",F17)
A18: Cyprus | B18: C17 — All paper & pulp | C18: C17 | D18: 19.948 | E18: 8.6 | F18: =E18/D18 | G18: Yes | H18: =A18&"|"&C18 | J18: =H18 | K18: =IF(ISBLANK(F18),"",F18)
A19: Cyprus | B19: C17_X_C1711 — Paper excl. pulp | C19: C17xP | D19: 19.854 | E19: 8.6 | F19: =E19/D19 | G19: Yes | H19: =A19&"|"&C19 | J19: =H19 | K19: =IF(ISBLANK(F19),"",F19)
A20: Cyprus | B20: C1711 — Pulp only | C20: C1711 | D20: 0.094 | E20: 0 | F20: =E20/D20 | G20: Yes | H20: =A20&"|"&C20 | J20: =H20 | K20: =IF(ISBLANK(F20),"",F20)
A21: Czechia | B21: C17 — All paper & pulp | C21: C17 | E21: 5206.2 | G21: No | H21: =A21&"|"&C21 | J21: =H21 | K21: =IF(ISBLANK(F21),"",F21)
A22: Czechia | B22: C17_X_C1711 — Paper excl. pulp | C22: C17xP | E22: 1674.6 | G22: No | H22: =A22&"|"&C22 | J22: =H22 | K22: =IF(ISBLANK(F22),"",F22)
A23: Czechia | B23: C1711 — Pulp only | C23: C1711 | E23: 0 | G23: No | H23: =A23&"|"&C23 | J23: =H23 | K23: =IF(ISBLANK(F23),"",F23)
A24: Denmark | B24: C17 — All paper & pulp | C24: C17 | D24: 2282.649 | E24: 1110.8 | F24: =E24/D24 | G24: Yes | H24: =A24&"|"&C24 | J24: =H24 | K24: =IF(ISBLANK(F24),"",F24)
A25: Denmark | B25: C17_X_C1711 — Paper excl. pulp | C25: C17xP | D25: 2282.649 | E25: 1110.8 | F25: =E25/D25 | G25: Yes | H25: =A25&"|"&C25 | J25: =H25 | K25: =IF(ISBLANK(F25),"",F25)
A26: Denmark | B26: C1711 — Pulp only | C26: C1711 | D26: 0 | E26: 0 | G26: Yes | H26: =A26&"|"&C26 | J26: =H26 | K26: =IF(ISBLANK(F26),"",F26)
A27: Estonia | B27: C17 — All paper & pulp | C27: C17 | D27: 1746.264 | E27: 420.4 | F27: =E27/D27 | G27: Yes | H27: =A27&"|"&C27 | J27: =H27 | K27: =IF(ISBLANK(F27),"",F27)
A28: Estonia | B28: C17_X_C1711 — Paper excl. pulp | C28: C17xP | D28: 828.94 | E28: 121.1 | F28: =E28/D28 | G28: Yes | H28: =A28&"|"&C28 | J28: =H28 | K28: =IF(ISBLANK(F28),"",F28)
A29: Estonia | B29: C1711 — Pulp only | C29: C1711 | D29: 917.323 | E29: 299.3 | F29: =E29/D29 | G29: Yes | H29: =A29&"|"&C29 | J29: =H29 | K29: =IF(ISBLANK(F29),"",F29)
A30: Finland | B30: C17 — All paper & pulp | C30: C17 | D30: 212799.21 | E30: 18002.6 | F30: =E30/D30 | G30: Yes | H30: =A30&"|"&C30 | J30: =H30 | K30: =IF(ISBLANK(F30),"",F30)
A31: Finland | B31: C17_X_C1711 — Paper excl. pulp | C31: C17xP | D31: 103077.95 | E31: 11307.1 | F31: =E31/D31 | G31: Yes | H31: =A31&"|"&C31 | J31: =H31 | K31: =IF(ISBLANK(F31),"",F31)
A32: Finland | B32: C1711 — Pulp only | C32: C1711 | D32: 109721.26 | E32: 6695.5 | F32: =E32/D32 | G32: Yes | H32: =A32&"|"&C32 | J32: =H32 | K32: =IF(ISBLANK(F32),"",F32)
A33: France | B33: C17 — All paper & pulp | C33: C17 | D33: 73551.671 | E33: 24104.5 | F33: =E33/D33 | G33: Yes | H33: =A33&"|"&C33 | J33: =H33 | K33: =IF(ISBLANK(F33),"",F33)
A34: France | B34: C17_X_C1711 — Paper excl. pulp | C34: C17xP | D34: 51435.385 | E34: 22445.7 | F34: =E34/D34 | G34: Yes | H34: =A34&"|"&C34 | J34: =H34 | K34: =IF(ISBLANK(F34),"",F34)
A35: France | B35: C1711 — Pulp only | C35: C1711 | D35: 22116.286 | E35: 0 | F35: =E35/D35 | G35: Yes | H35: =A35&"|"&C35 | J35: =H35 | K35: =IF(ISBLANK(F35),"",F35)
A36: Germany | B36: C17 — All paper & pulp | C36: C17 | D36: 181262.16 | E36: 69138 | F36: =E36/D36 | G36: Yes | H36: =A36&"|"&C36 | J36: =H36 | K36: =IF(ISBLANK(F36),"",F36)
A37: Germany | B37: C17_X_C1711 — Paper excl. pulp | C37: C17xP | D37: 162640.72 | E37: 66843.9 | F37: =E37/D37 | G37: Yes | H37: =A37&"|"&C37 | J37: =H37 | K37: =IF(ISBLANK(F37),"",F37)
A38: Germany | B38: C1711 — Pulp only | C38: C1711 | D38: 18621.441 | E38: 2294.1 | F38: =E38/D38 | G38: Yes | H38: =A38&"|"&C38 | J38: =H38 | K38: =IF(ISBLANK(F38),"",F38)
A39: Greece | B39: C17 — All paper & pulp | C39: C17 | E39: 942.1 | G39: No | H39: =A39&"|"&C39 | J39: =H39 | K39: =IF(ISBLANK(F39),"",F39)
A40: Greece | B40: C17_X_C1711 — Paper excl. pulp | C40: C17xP | E40: 942.1 | G40: No | H40: =A40&"|"&C40 | J40: =H40 | K40: =IF(ISBLANK(F40),"",F40)
...

Sheet Facilities
A1: Facilities — formula-driven (heat = output × SEC; replaceable = heat × fossil share × replace frac)
A2: source_id | B2: source_name | C2: country_corrected | D2: classification | E2: nace_used | F2: annual_output_t | G2: proxy_capacity | H2: SEC (MWh/t) | I2: Fossil Share | J2: FS Source | K2: Replace Frac | L2: Heat Demand (MWh) | M2: Replaceable (MWh) | N2: keep? | O2: status_flag | P2: lookup_key | Q2: justification
A3: 44375330 | B3: Mondi Neusiedler Pulp Mill | C3: Austria | D3: Integrated | E3: C17 | F3: 260039.2 | G3: PROXY | H3: =VLOOKUP(D3,Parameters!$A$5:$B$8,2,FALSE()) | I3: =IFERROR(IF(VLOOKUP(P3,Fossil_Shares!$J$3:$K$98,2,FALSE())="",VLOOKUP(E3,Parameters!$A$12:$B$14,2,FALSE()),VLOOKUP(P3,Fossil_Shares!$J$3:$K$98,2,FALSE())),VLOOKUP(E3,Parameters!$A$12:$B$14,2,FALSE())) | J3: =IFERROR(IF(VLOOKUP(P3,Fossil_Shares!$J$3:$K$98,2,FALSE())="","EU27 fallback","Eurostat"),"EU27 fallback") | K3: =VLOOKUP(D3,Parameters!$A$18:$B$21,2,FALSE()) | L3: =IF(N3="YES",F3*H3,0) | M3: =L3*I3*K3 | N3: YES | P3: =C3&"|"&E3 | Q3: Kematen mill: sulphite pulp + uncoated fine paper on same site (Mondi)
A4: 44375331 | B4: Papierfabrik Wattens GmbH & Co KG - Delfort | C4: Austria | D4: Paper/Board | E4: C17xP | F4: 260039.2 | G4: PROXY | H4: =VLOOKUP(D4,Parameters!$A$5:$B$8,2,FALSE()) | I4: =IFERROR(IF(VLOOKUP(P4,Fossil_Shares!$J$3:$K$98,2,FALSE())="",VLOOKUP(E4,Parameters!$A$12:$B$14,2,FALSE()),VLOOKUP(P4,Fossil_Shares!$J$3:$K$98,2,FALSE())),VLOOKUP(E4,Parameters!$A$12:$B$14,2,FALSE())) | J4: =IFERROR(IF(VLOOKUP(P4,Fossil_Shares!$J$3:$K$98,2,FALSE())="","EU27 fallback","Eurostat"),"EU27 fallback") | K4: =VLOOKUP(D4,Parameters!$A$18:$B$21,2,FALSE()) | L4: =IF(N4="YES",F4*H4,0) | M4: =L4*I4*K4 | N4: YES | O4: NEEDS_VERIFICATION | P4: =C4&"|"&E4 | Q4: Delfort specialty/thin paper mill; semi-chem tag but primarily paper output — verify on-site pulp
A5: 44375328 | B5: Laakirchen Papier AG Pulp Mill | C5: Austria | D5: Paper/Board | E5: C17xP | F5: 260039.2 | G5: PROXY | H5: =VLOOKUP(D5,Parameters!$A$5:$B$8,2,FALSE()) | I5: =IFERROR(IF(VLOOKUP(P5,Fossil_Shares!$J$3:$K$98,2,FALSE())="",VLOOKUP(E5,Parameters!$A$12:$B$14,2,FALSE()),VLOOKUP(P5,Fossil_Shares!$J$3:$K$98,2,FALSE())),VLOOKUP(E5,Parameters!$A$12:$B$14,2,FALSE())) | J5: =IFERROR(IF(VLOOKUP(P5,Fossil_Shares!$J$3:$K$98,2,FALSE())="","EU27 fallback","Eurostat"),"EU27 fallback") | K5: =VLOOKUP(D5,Parameters!$A$18:$B$21,2,FALSE()) | L5: =IF(N5="YES",F5*H5,0) | M5: =L5*I5*K5 | N5: YES | P5: =C5&"|"&E5 | Q5: Recycled-fibre SC paper & containerboard; no virgin pulp line (Heinzel Group)
A6: 44375329 | B6: UPM-Kymmene Steyrermuhl Austria Pulp Mill | C6: Austria | D6: Paper/Board | E6: C17xP | F6: 260039.2 | G6: PROXY | H6: =VLOOKUP(D6,Parameters!$A$5:$B$8,2,FALSE()) | I6: =IFERROR(IF(VLOOKUP(P6,Fossil_Shares!$J$3:$K$98,2,FALSE())="",VLOOKUP(E6,Parameters!$A$12:$B$14,2,FALSE()),VLOOKUP(P6,Fossil_Shares!$J$3:$K$98,2,FALSE())),VLOOKUP(E6,Parameters!$A$12:$B$14,2,FALSE())) | J6: =IFERROR(IF(VLOOKUP(P6,Fossil_Shares!$J$3:$K$98,2,FALSE())="","EU27 fallback","Eurostat"),"EU27 fallback") | K6: =VLOOKUP(D6,Parameters!$A$18:$B$21,2,FALSE()) | L6: =IF(N6="YES",F6*H6,0) | M6: =L6*I6*K6 | N6: YES | P6: =C6&"|"&E6 | Q6: Graphic paper mill; converted to Heinzel packaging paper hub end-2023 (PaperFIRST)
A7: 44375327 | B7: Ybbstaler Zellstoff Pulp Mill | C7: Austria | D7: Pulp | E7: C1711 | F7: 260039.2 | G7: PROXY | H7: =VLOOKUP(D7,Parameters!$A$5:$B$8,2,FALSE()) | I7: =IFERROR(IF(VLOOKUP(P7,Fossil_Shares!$J$3:$K$98,2,FALSE())="",VLOOKUP(E7,Parameters!$A$12:$B$14,2,FALSE()),VLOOKUP(P7,Fossil_Shares!$J$3:$K$98,2,FALSE())),VLOOKUP(E7,Parameters!$A$12:$B$14,2,FALSE())) | J7: =IFERROR(IF(VLOOKUP(P7,Fossil_Shares!$J$3:$K$98,2,FALSE())="","EU27 fallback","Eurostat"),"EU27 fallback") | K7: =VLOOKUP(D7,Parameters!$A$18:$B$21,2,FALSE()) | L7: =IF(N7="YES",F7*H7,0) | M7: =L7*I7*K7 | N7: YES | O7: NEEDS_VERIFICATION | P7: =C7&"|"&E7 | Q7: Standalone sulphite pulp operation historically linked to Mondi Neusiedler; verify merger status
A8: 44375537 | B8: SCA Laakirchen Papier AG | C8: Austria | D8: Paper/Board | E8: C17xP | F8: 485789.47 | G8: PROXY | H8: =VLOOKUP(D8,Parameters!$A$5:$B$8,2,FALSE()) | I8: =IFERROR(IF(VLOOKUP(P8,Fossil_Shares!$J$3:$K$98,2,FALSE())="",VLOOKUP(E8,Parameters!$A$12:$B$14,2,FALSE()),VLOOKUP(P8,Fossil_Shares!$J$3:$K$98,2,FALSE())),VLOOKUP(E8,Parameters!$A$12:$B$14,2,FALSE())) | J8: =IFERROR(IF(VLOOKUP(P8,Fossil_Shares!$J$3:$K$98,2,FALSE())="","EU27 fallback","Eurostat"),"EU27 fallback") | K8: =VLOOKUP(D8,Parameters!$A$18:$B$21,2,FALSE()) | L8: =IF(N8="YES",F8*H8,0) | M8: =L8*I8*K8 | N8: no | O8: DUPLICATE|COUNTRY_CORRECTED | P8: =C8&"|"&E8 | Q8: COUNTRY CORRECTED to AUT (Laakirchen, Austria). Same SC/containerboard mill as 44375328 — possible duplicate
A9: 44375533 | B9: Burgo Ardennes SA | C9: Belgium | D9: Integrated | E9: C17 | F9: 256350.22 | G9: ok | H9: =VLOOKUP(D9,Parameters!$A$5:$B$8,2,FALSE()) | I9: =IFERROR(IF(VLOOKUP(P9,Fossil_Shares!$J$3:$K$98,2,FALSE())="",VLOOKUP(E9,Parameters!$A$12:$B$14,2,FALSE()),VLOOKUP(P9,Fossil_Shares!$J$3:$K$98,2,FALSE())),VLOOKUP(E9,Parameters!$A$12:$B$14,2,FALSE())) | J9: =IFERROR(IF(VLOOKUP(P9,Fossil_Shares!$J$3:$K$98,2,FALSE())="","EU27 fallback","Eurostat"),"EU27 fallback") | K9: =VLOOKUP(D9,Parameters!$A$18:$B$21,2,FALSE()) | L9: =IF(N9="YES",F9*H9,0) | M9: =L9*I9*K9 | N9: no | O9: DUPLICATE|COUNTRY_CORRECTED | P9: =C9&"|"&E9 | Q9: COUNTRY CORRECTED to BEL (Virton, Belgium). Integrated pulp + CWF paper — duplicate of 44375332
A10: 44375332 | B10: Burgo Ardennes Pulp Mill | C10: Belgium | D10: Integrated | E10: C17 | F10: 324790 | G10: ok | H10: =VLOOKUP(D10,Parameters!$A$5:$B$8,2,FALSE()) | I10: =IFERROR(IF(VLOOKUP(P10,Fossil_Shares!$J$3:$K$98,2,FALSE())="",VLOOKUP(E10,Parameters!$A$12:$B$14,2,FALSE()),VLOOKUP(P10,Fossil_Shares!$J$3:$K$98,2,FALSE())),VLOOKUP(E10,Parameters!$A$12:$B$14,2,FALSE())) | J10: =IFERROR(IF(VLOOKUP(P10,Fossil_Shares!$J$3:$K$98,2,FALSE())="","EU27 fallback","Eurostat"),"EU27 fallback") | K10: =VLOOKUP(D10,Parameters!$A$18:$B$21,2,FALSE()) | L10: =IF(N10="YES",F10*H10,0) | M10: =L10*I10*K10 | N10: YES | P10: =C10&"|"&E10 | Q10: Virton: kraft pulp + coated woodfree paper, 400kt pulp + 380kt CWF (Burgo Group)
A11: 44375333 | B11: Svilocell EAD - Subsidiary of Svilosa AD | C11: Bulgaria | D11: Pulp | E11: C1711 | F11: 93048.425 | G11: PROXY | H11: =VLOOKUP(D11,Parameters!$A$5:$B$8,2,FALSE()) | I11: =IFERROR(IF(VLOOKUP(P11,Fossil_Shares!$J$3:$K$98,2,FALSE())="",VLOOKUP(E11,Parameters!$A$12:$B$14,2,FALSE()),VLOOKUP(P11,Fossil_Shares!$J$3:$K$98,2,FALSE())),VLOOKUP(E11,Parameters!$A$12:$B$14,2,FALSE())) | J11: =IFERROR(IF(VLOOKUP(P11,Fossil_Shares!$J$3:$K$98,2,FALSE())="","EU27 fallback","Eurostat"),"EU27 fallback") | K11: =VLOOKUP(D11,Parameters!$A$18:$B$21,2,FALSE()) | L11: =IF(N11="YES",F11*H11,0) | M11: =L11*I11*K11 | N11: YES | P11: =C11&"|"&E11 | Q11: Bleached kraft market pulp; no integrated paper line known
A12: 44375334 | B12: Stambolijski Kraft Pulp & Paper Mill | C12: Bulgaria | D12: Integrated | E12: C17 | F12: 93048.425 | G12: PROXY | H12: =VLOOKUP(D12,Parameters!$A$5:$B$8,2,FALSE()) | I12: =IFERROR(IF(VLOOKUP(P12,Fossil_Shares!$J$3:$K$98,2,FALSE())="",VLOOKUP(E12,Parameters!$A$12:$B$14,2,FALSE()),VLOOKUP(P12,Fossil_Shares!$J$3:$K$98,2,FALSE())),VLOOKUP(E12,Parameters!$A$12:$B$14,2,FALSE())) | J12: =IFERROR(IF(VLOOKUP(P12,Fossil_Shares!$J$3:$K$98,2,FALSE())="","EU27 fallback","Eurostat"),"EU27 fallback") | K12: =VLOOKUP(D12,Parameters!$A$18:$B$21,2,FALSE()) | L12: =IF(N12="YES",F12*H12,0) | M12: =L12*I12*K12 | N12: no | O12: CLOSED | P12: =C12&"|"&E12 | Q12: Name states Pulp & Paper; historic kraft site — verify current operational status
A13: 44375335 | B13: Svistov Pulp Plant | C13: Bulgaria | D13: Pulp | E13: C1711 | F13: 93048.425 | G13: PROXY | H13: =VLOOKUP(D13,Parameters!$A$5:$B$8,2,FALSE()) | I13: =IFERROR(IF(VLOOKUP(P13,Fossil_Shares!$J$3:$K$98,2,FALSE())="",VLOOKUP(E13,Parameters!$A$12:$B$14,2,FALSE()),VLOOKUP(P13,Fossil_Shares!$J$3:$K$98,2,FALSE())),VLOOKUP(E13,Parameters!$A$12:$B$14,2,FALSE())) | J13: =IFERROR(IF(VLOOKUP(P13,Fossil_Shares!$J$3:$K$98,2,FALSE())="","EU27 fallback","Eurostat"),"EU27 fallback") | K13: =VLOOKUP(D13,Parameters!$A$18:$B$21,2,FALSE()) | L13: =IF(N13="YES",F13*H13,0) | M13: =L13*I13*K13 | N13: no | O13: DUPLICATE|NEEDS_VERIFICATION | P13: =C13&"|"&E13 | Q13: Same Svilosa/Svishtov complex as Svilocell — likely duplicate; verify and de-duplicate
A14: 44375502 | B14: OP Papírna s.r.o. - Delfort | C14: Czechia | D14: Paper/Board | E14: C17xP | F14: 219922.84 | G14: PROXY | H14: =VLOOKUP(D14,Parameters!$A$5:$B$8,2,FALSE()) | I14: =IFERROR(IF(VLOOKUP(P14,Fossil_Shares!$J$3:$K$98,2,FALSE())="",VLOOKUP(E14,Parameters!$A$12:$B$14,2,FALSE()),VLOOKUP(P14,Fossil_Shares!$J$3:$K$98,2,FALSE())),VLOOKUP(E14,Parameters!$A$12:$B$14,2,FALSE())) | J14: =IFERROR(IF(VLOOKUP(P14,Fossil_Shares!$J$3:$K$98,2,FALSE())="","EU27 fallback","Eurostat"),"EU27 fallback") | K14: =VLOOKUP(D14,Parameters!$A$18:$B$21,2,FALSE()) | L14: =IF(N14="YES",F14*H14,0) | M14: =L14*I14*K14 | N14: YES | O14: NEEDS_VERIFICATION | P14: =C14&"|"&E14 | Q14: Delfort specialty thin-paper mill (Olšany); primarily paper — verify on-site pulp
A15: 44375503 | B15: Biocel Paskov Pulp Mill | C15: Czechia | D15: Pulp | E15: C1711 | F15: 219922.84 | G15: PROXY | H15: =VLOOKUP(D15,Parameters!$A$5:$B$8,2,FALSE()) | I15: =IFERROR(IF(VLOOKUP(P15,Fossil_Shares!$J$3:$K$98,2,FALSE())="",VLOOKUP(E15,Parameters!$A$12:$B$14,2,FALSE()),VLOOKUP(P15,Fossil_Shares!$J$3:$K$98,2,FALSE())),VLOOKUP(E15,Parameters!$A$12:$B$14,2,FALSE())) | J15: =IFERROR(IF(VLOOKUP(P15,Fossil_Shares!$J$3:$K$98,2,FALSE())="","EU27 fallback","Eurostat"),"EU27 fallback") | K15: =VLOOKUP(D15,Parameters!$A$18:$B$21,2,FALSE()) | L15: =IF(N15="YES",F15*H15,0) | M15: =L15*I15*K15 | N15: YES | P15: =C15&"|"&E15 | Q15: Lenzing biorefinery: dissolving + paper-grade pulp only; no papermaking (Lenzing/Innovation in Textiles)
A16: 44375557 | B16: Biocel Paskov 2 | C16: Czechia | D16: Pulp | E16: C1711 | G16: ok | H16: =VLOOKUP(D16,Parameters!$A$5:$B$8,2,FALSE()) | I16: =IFERROR(IF(VLOOKUP(P16,Fossil_Shares!$J$3:$K$98,2,FALSE())="",VLOOKUP(E16,Parameters!$A$12:$B$14,2,FALSE()),VLOOKUP(P16,Fossil_Shares!$J$3:$K$98,2,FALSE())),VLOOKUP(E16,Parameters!$A$12:$B$14,2,FALSE())) | J16: =IFERROR(IF(VLOOKUP(P16,Fossil_Shares!$J$3:$K$98,2,FALSE())="","EU27 fallback","Eurostat"),"EU27 fallback") | K16: =VLOOKUP(D16,Parameters!$A$18:$B$21,2,FALSE()) | L16: =IF(N16="YES",F16*H16,0) | M16: =L16*I16*K16 | N16: no | O16: DUPLICATE|COUNTRY_CORRECTED | P16: =C16&"|"&E16 | Q16: COUNTRY CORRECTED to CZE. Duplicate of 44375503 (Biocel Paskov dissolving/paper pulp, Lenzing)
A17: 44375520 | B17: Golbey Pulp and Paper Mill | C17: France | D17: Paper/Board | E17: C17xP | F17: 82573.585 | G17: ok | H17: =VLOOKUP(D17,Parameters!$A$5:$B$8,2,FALSE()) | I17: =IFERROR(IF(VLOOKUP(P17,Fossil_Shares!$J$3:$K$98,2,FALSE())="",VLOOKUP(E17,Parameters!$A$12:$B$14,2,FALSE()),VLOOKUP(P17,Fossil_Shares!$J$3:$K$98,2,FALSE())),VLOOKUP(E17,Parameters!$A$12:$B$14,2,FALSE())) | J17: =IFERROR(IF(VLOOKUP(P17,Fossil_Shares!$J$3:$K$98,2,FALSE())="","EU27 fallback","Eurostat"),"EU27 fallback") | K17: =VLOOKUP(D17,Parameters!$A$18:$B$21,2,FALSE()) | L17: =IF(N17="YES",F17*H17,0) | M17: =L17*I17*K17 | N17: no | P17: =C17&"|"&E17 | Q17: Norske Skog Golbey: newsprint/recycled containerboard; no chemical pulp line (TMP/recovered fibre)
A18: 44375543 | B18: Norske Skog Golbey | C18: France | D18: Paper/Board | E18: C17xP | F18: 148763.11 | G18: PROXY | H18: =VLOOKUP(D18,Parameters!$A$5:$B$8,2,FALSE()) | I18: =IFERROR(IF(VLOOKUP(P18,Fossil_Shares!$J$3:$K$98,2,FALSE())="",VLOOKUP(E18,Parameters!$A$12:$B$14,2,FALSE()),VLOOKUP(P18,Fossil_Shares!$J$3:$K$98,2,FALSE())),VLOOKUP(E18,Parameters!$A$12:$B$14,2,FALSE())) | J18: =IFERROR(IF(VLOOKUP(P18,Fossil_Shares!$J$3:$K$98,2,FALSE())="","EU27 fallback","Eurostat"),"EU27 fallback") | K18: =VLOOKUP(D18,Parameters!$A$18:$B$21,2,FALSE()) | L18: =IF(N18="YES",F18*H18,0) | M18: =L18*I18*K18 | N18: YES | O18: DUPLICATE|COUNTRY_CORRECTED | P18: =C18&"|"&E18 | Q18: COUNTRY CORRECTED to FRA (Golbey, France). Newsprint/recycled containerboard — duplicate of 44375520
A19: 44375517 | B19: Mimizan Pulp and Paper Mill - Paper Bags | C19: France | D19: Integrated | E19: C17 | F19: 171453.8 | G19: ok | H19: =VLOOKUP(D19,Parameters!$A$5:$B$8,2,FALSE()) | I19: =IFERROR(IF(VLOOKUP(P19,Fossil_Shares!$J$3:$K$98,2,FALSE())="",VLOOKUP(E19,Parameters!$A$12:$B$14,2,FALSE()),VLOOKUP(P19,Fossil_Shares!$J$3:$K$98,2,FALSE())),VLOOKUP(E19,Parameters!$A$12:$B$14,2,FALSE())) | J19: =IFERROR(IF(VLOOKUP(P19,Fossil_Shares!$J$3:$K$98,2,FALSE())="","EU27 fallback","Eurostat"),"EU27 fallback") | K19: =VLOOKUP(D19,Parameters!$A$18:$B$21,2,FALSE()) | L19: =IF(N19="YES",F19*H19,0) | M19: =L19*I19*K19 | N19: YES | P19: =C19&"|"&E19 | Q19: Gascogne Papier Mimizan: integrated kraft pulp + natural kraft/sack paper (Gascogne Papier; ANDRITZ)
A20: 44375523 | B20: Facture Biganos Pulp and Paper Mill | C20: France | D20: Integrated | E20: C17 | F20: 485789.47 | G20: PROXY | H20: =VLOOKUP(D20,Parameters!$A$5:$B$8,2,FALSE()) | I20: =IFERROR(IF(VLOOKUP(P20,Fossil_Shares!$J$3:$K$98,2,FALSE())="",VLOOKUP(E20,Parameters!$A$12:$B$14,2,FALSE()),VLOOKUP(P20,Fossil_Shares!$J$3:$K$98,2,FALSE())),VLOOKUP(E20,Parameters!$A$12:$B$14,2,FALSE())) | J20: =IFERROR(IF(VLOOKUP(P20,Fossil_Shares!$J$3:$K$98,2,FALSE())="","EU27 fallback","Eurostat"),"EU27 fallback") | K20: =VLOOKUP(D20,Parameters!$A$18:$B$21,2,FALSE()) | L20: =IF(N20="YES",F20*H20,0) | M20: =L20*I20*K20 | N20: YES | P20: =C20&"|"&E20 | Q20: Smurfit Kappa Facture/Biganos: integrated kraft pulp + kraftliner (Pulp&PaperNews; SUEZ)
A21: 44375524 | B21: Saint Gaudens Pulp Mill | C21: France | D21: Pulp | E21: C1711 | F21: 485789.47 | G21: PROXY | H21: =VLOOKUP(D21,Parameters!$A$5:$B$8,2,FALSE()) | I21: =IFERROR(IF(VLOOKUP(P21,Fossil_Shares!$J$3:$K$98,2,FALSE())="",VLOOKUP(E21,Parameters!$A$12:$B$14,2,FALSE()),VLOOKUP(P21,Fossil_Shares!$J$3:$K$98,2,FALSE())),VLOOKUP(E21,Parameters!$A$12:$B$14,2,FALSE())) | J21: =IFERROR(IF(VLOOKUP(P21,Fossil_Shares!$J$3:$K$98,2,FALSE())="","EU27 fallback","Eurostat"),"EU27 fallback") | K21: =VLOOKUP(D21,Parameters!$A$18:$B$21,2,FALSE()) | L21: =IF(N21="YES",F21*H21,0) | M21: =L21*I21*K21 | N21: YES | O21: NEEDS_VERIFICATION | P21: =C21&"|"&E21 | Q21: Fibre Excellence Saint-Gaudens: kraft market pulp mill; no integrated paper — verify operator/status
A22: 44375522 | B22: Tarascon Pulp Mill | C22: France | D22: Pulp | E22: C1711 | F22: 485789.47 | G22: PROXY | H22: =VLOOKUP(D22,Parameters!$A$5:$B$8,2,FALSE()) | I22: =IFERROR(IF(VLOOKUP(P22,Fossil_Shares!$J$3:$K$98,2,FALSE())="",VLOOKUP(E22,Parameters!$A$12:$B$14,2,FALSE()),VLOOKUP(P22,Fossil_Shares!$J$3:$K$98,2,FALSE())),VLOOKUP(E22,Parameters!$A$12:$B$14,2,FALSE())) | J22: =IFERROR(IF(VLOOKUP(P22,Fossil_Shares!$J$3:$K$98,2,FALSE())="","EU27 fallback","Eurostat"),"EU27 fallback") | K22: =VLOOKUP(D22,Parameters!$A$18:$B$21,2,FALSE()) | L22: =IF(N22="YES",F22*H22,0) | M22: =L22*I22*K22 | N22: YES | O22: NEEDS_VERIFICATION | P22: =C22&"|"&E22 | Q22: Fibre Excellence Tarascon: kraft market pulp mill; no paper — verify operational status
A23: 44375527 | B23: WEPA Greenfield SAS - WEPA Group | C23: France | D23: Tissue | E23: C17xP | F23: 485789.47 | G23: PROXY | H23: =VLOOKUP(D23,Parameters!$A$5:$B$8,2,FALSE()) | I23: =IFERROR(IF(VLOOKUP(P23,Fossil_Shares!$J$3:$K$98,2,FALSE())="",VLOOKUP(E23,Parameters!$A$12:$B$14,2,FALSE()),VLOOKUP(P23,Fossil_Shares!$J$3:$K$98,2,FALSE())),VLOOKUP(E23,Parameters!$A$12:$B$14,2,FALSE())) | J23: =IFERROR(IF(VLOOKUP(P23,Fossil_Shares!$J$3:$K$98,2,FALSE())="","EU27 fallback","Eurostat"),"EU27 fallback") | K23: =VLOOKUP(D23,Parameters!$A$18:$B$21,2,FALSE()) | L23: =IF(N23="YES",F23*H23,0) | M23: =L23*I23*K23 | N23: YES | P23: =C23&"|"&E23 | Q23: WEPA Greenfield (Château-Thierry): recycled tissue/hygiene paper — WEPA is Europe's #3 tissue producer
A24: 44375526 | B24: Saillat-sur-Vienne Pulp and Paper Mill | C24: France | D24: Integrated | E24: C17 | F24: 520240.16 | G24: ok | H24: =VLOOKUP(D24,Parameters!$A$5:$B$8,2,FALSE()) | I24: =IFERROR(IF(VLOOKUP(P24,Fossil_Shares!$J$3:$K$98,2,FALSE())="",VLOOKUP(E24,Parameters!$A$12:$B$14,2,FALSE()),VLOOKUP(P24,Fossil_Shares!$J$3:$K$98,2,FALSE())),VLOOKUP(E24,Parameters!$A$12:$B$14,2,FALSE())) | J24: =IFERROR(IF(VLOOKUP(P24,Fossil_Shares!$J$3:$K$98,2,FALSE())="","EU27 fallback","Eurostat"),"EU27 fallback") | K24: =VLOOKUP(D24,Parameters!$A$18:$B$21,2,FALSE()) | L24: =IF(N24="YES",F24*H24,0) | M24: =L24*I24*K24 | N24: YES | P24: =C24&"|"&E24 | Q24: Smurfit Kappa Saillat: integrated kraft pulp + kraftliner (Packaging Europe; HYFLEXPOWER project)
A25: 44375521 | B25: Alizay Papier SASU - VPK Group | C25: France | D25: Paper/Board | E25: C17xP | F25: 980162.62 | G25: PROXY | H25: =VLOOKUP(D25,Parameters!$A$5:$B$8,2,FALSE()) | I25: =IFERROR(IF(VLOOKUP(P25,Fossil_Shares!$J$3:$K$98,2,FALSE())="",VLOOKUP(E25,Parameters!$A$12:$B$14,2,FALSE()),VLOOKUP(P25,Fossil_Shares!$J$3:$K$98,2,FALSE())),VLOOKUP(E25,Parameters!$A$12:$B$14,2,FALSE())) | J25: =IFERROR(IF(VLOOKUP(P25,Fossil_Shares!$J$3:$K$98,2,FALSE())="","EU27 fallback","Eurostat"),"EU27 fallback") | K25: =VLOOKUP(D25,Parameters!$A$18:$B$21,2,FALSE()) | L25: =IF(N25="YES",F25*H25,0) | M25: =L25*I25*K25 | N25: YES | P25: =C25&"|"&E25 | Q25: VPK Alizay: recycled containerboard; no virgin pulp — Pulp misc. = RCF prep
A26: 44375516 | B26: Rayonier Advanced Materials | C26: France | D26: Pulp | E26: C1711 | G26: ok | H26: =VLOOKUP(D26,Parameters!$A$5:$B$8,2,FALSE()) | I26: =IFERROR(IF(VLOOKUP(P26,Fossil_Shares!$J$3:$K$98,2,FALSE())="",VLOOKUP(E26,Parameters!$A$12:$B$14,2,FALSE()),VLOOKUP(P26,Fossil_Shares!$J$3:$K$98,2,FALSE())),VLOOKUP(E26,Parameters!$A$12:$B$14,2,FALSE())) | J26: =IFERROR(IF(VLOOKUP(P26,Fossil_Shares!$J$3:$K$98,2,FALSE())="","EU27 fallback","Eurostat"),"EU27 fallback") | K26: =VLOOKUP(D26,Parameters!$A$18:$B$21,2,FALSE()) | L26: =IF(N26="YES",F26*H26,0) | M26: =L26*I26*K26 | N26: YES | P26: =C26&"|"&E26 | Q26: RYAM Tartas: dissolving/high-purity cellulose (acid-sulphite pine) + biomaterials; no paper (RYAM; MDPI)
A27: 44375510 | B27: GRuNPERGA Papier Pulp Mill | C27: Germany | D27: Paper/Board | E27: C17xP | F27: 54016.842 | G27: ok | H27: =VLOOKUP(D27,Parameters!$A$5:$B$8,2,FALSE()) | I27: =IFERROR(IF(VLOOKUP(P27,Fossil_Shares!$J$3:$K$98,2,FALSE())="",VLOOKUP(E27,Parameters!$A$12:$B$14,2,FALSE()),VLOOKUP(P27,Fossil_Shares!$J$3:$K$98,2,FALSE())),VLOOKUP(E27,Parameters!$A$12:$B$14,2,FALSE())) | J27: =IFERROR(IF(VLOOKUP(P27,Fossil_Shares!$J$3:$K$98,2,FALSE())="","EU27 fallback","Eurostat"),"EU27 fallback") | K27: =VLOOKUP(D27,Parameters!$A$18:$B$21,2,FALSE()) | L27: =IF(N27="YES",F27*H27,0) | M27: =L27*I27*K27 | N27: YES | P27: =C27&"|"&E27 | Q27: Grünberg specialty paper mill; mechanical tag — treat as paper pending verification
A28: 44375515 | B28: Katz GmbH & Co. KG | C28: Germany | D28: Integrated | E28: C17 | F28: 164844.5 | G28: PROXY | H28: =VLOOKUP(D28,Parameters!$A$5:$B$8,2,FALSE()) | I28: =IFERROR(IF(VLOOKUP(P28,Fossil_Shares!$J$3:$K$98,2,FALSE())="",VLOOKUP(E28,Parameters!$A$12:$B$14,2,FALSE()),VLOOKUP(P28,Fossil_Shares!$J$3:$K$98,2,FALSE())),VLOOKUP(E28,Parameters!$A$12:$B$14,2,FALSE())) | J28: =IFERROR(IF(VLOOKUP(P28,Fossil_Shares!$J$3:$K$98,2,FALSE())="","EU27 fallback","Eurostat"),"EU27 fallback") | K28: =VLOOKUP(D28,Parameters!$A$18:$B$21,2,FALSE()) | L28: =IF(N28="YES",F28*H28,0) | M28: =L28*I28*K28 | N28: YES | P28: =C28&"|"&E28 | Q28: Weisenbach: own groundwood pulp + board for beer mats/display board (Katz Group)
A29: 44375504 | B29: Sappi Alfeld Kraft Pulp and Paper Mill | C29: Germany | D29: Integrated | E29: C17 | F29: 164844.5 | G29: PROXY | H29: =VLOOKUP(D29,Parameters!$A$5:$B$8,2,FALSE()) | I29: =IFERROR(IF(VLOOKUP(P29,Fossil_Shares!$J$3:$K$98,2,FALSE())="",VLOOKUP(E29,Parameters!$A$12:$B$14,2,FALSE()),VLOOKUP(P29,Fossil_Shares!$J$3:$K$98,2,FALSE())),VLOOKUP(E29,Parameters!$A$12:$B$14,2,FALSE())) | J29: =IFERROR(IF(VLOOKUP(P29,Fossil_Shares!$J$3:$K$98,2,FALSE())="","EU27 fallback","Eurostat"),"EU27 fallback") | K29: =VLOOKUP(D29,Parameters!$A$18:$B$21,2,FALSE()) | L29: =IF(N29="YES",F29*H29,0) | M29: =L29*I29*K29 | N29: YES | P29: =C29&"|"&E29 | Q29: On-site bleached pulp + coated/uncoated specialty & packaging papers (Sappi mill page)
A30: 44375508 | B30: Lenk Paper GmbH - Papierfabrik Schleipen | C30: Germany | D30: Paper/Board | E30: C17xP | F30: 164844.5 | G30: PROXY | H30: =VLOOKUP(D30,Parameters!$A$5:$B$8,2,FALSE()) | I30: =IFERROR(IF(VLOOKUP(P30,Fossil_Shares!$J$3:$K$98,2,FALSE())="",VLOOKUP(E30,Parameters!$A$12:$B$14,2,FALSE()),VLOOKUP(P30,Fossil_Shares!$J$3:$K$98,2,FALSE())),VLOOKUP(E30,Parameters!$A$12:$B$14,2,FALSE())) | J30: =IFERROR(IF(VLOOKUP(P30,Fossil_Shares!$J$3:$K$98,2,FALSE())="","EU27 fallback","Eurostat"),"EU27 fallback") | K30: =VLOOKUP(D30,Parameters!$A$18:$B$21,2,FALSE()) | L30: =IF(N30="YES",F30*H30,0) | M30: =L30*I30*K30 | N30: YES | O30: NEEDS_VERIFICATION | P30: =C30&"|"&E30 | Q30: Specialty/décor paper; chemical + mechanical tag — verify on-site pulp (could be Integrated)
A31: 44375506 | B31: Heinrich Schaller Pappenfabrik e.K. Pulp Mill | C31: Germany | D31: Paper/Board | E31: C17xP | F31: 164844.5 | G31: PROXY | H31: =VLOOKUP(D31,Parameters!$A$5:$B$8,2,FALSE()) | I31: =IFERROR(IF(VLOOKUP(P31,Fossil_Shares!$J$3:$K$98,2,FALSE())="",VLOOKUP(E31,Parameters!$A$12:$B$14,2,FALSE()),VLOOKUP(P31,Fossil_Shares!$J$3:$K$98,2,FALSE())),VLOOKUP(E31,Parameters!$A$12:$B$14,2,FALSE())) | J31: =IFERROR(IF(VLOOKUP(P31,Fossil_Shares!$J$3:$K$98,2,FALSE())="","EU27 fallback","Eurostat"),"EU27 fallback") | K31: =VLOOKUP(D31,Parameters!$A$18:$B$21,2,FALSE()) | L31: =IF(N31="YES",F31*H31,0) | M31: =L31*I31*K31 | N31: YES | P31: =C31&"|"&E31 | Q31: Pappenfabrik = board mill; likely mechanical-pulp board (integrated possible)
A32: 44375507 | B32: Dynos GmbH - Niederlassung Bad Durkheim | C32: Germany | D32: Paper/Board | E32: C17xP | F32: 164844.5 | G32: PROXY | H32: =VLOOKUP(D32,Parameters!$A$5:$B$8,2,FALSE()) | I32: =IFERROR(IF(VLOOKUP(P32,Fossil_Shares!$J$3:$K$98,2,FALSE())="",VLOOKUP(E32,Parameters!$A$12:$B$14,2,FALSE()),VLOOKUP(P32,Fossil_Shares!$J$3:$K$98,2,FALSE())),VLOOKUP(E32,Parameters!$A$12:$B$14,2,FALSE())) | J32: =IFERROR(IF(VLOOKUP(P32,Fossil_Shares!$J$3:$K$98,2,FALSE())="","EU27 fallback","Eurostat"),"EU27 fallback") | K32: =VLOOKUP(D32,Parameters!$A$18:$B$21,2,FALSE()) | L32: =IF(N32="YES",F32*H32,0) | M32: =L32*I32*K32 | N32: YES | O32: NEEDS_VERIFICATION | P32: =C32&"|"&E32 | Q32: Semi-chem tag; likely board/moulded-fibre — verify production type
A33: 44375509 | B33: Sprick GmbH Bielefelder Papier- und Wellpappenwerke & Co.- Hauptverwaltung | C33: Germany | D33: Paper/Board | E33: C17xP | F33: 164844.5 | G33: PROXY | H33: =VLOOKUP(D33,Parameters!$A$5:$B$8,2,FALSE()) | I33: =IFERROR(IF(VLOOKUP(P33,Fossil_Shares!$J$3:$K$98,2,FALSE())="",VLOOKUP(E33,Parameters!$A$12:$B$14,2,FALSE()),VLOOKUP(P33,Fossil_Shares!$J$3:$K$98,2,FALSE())),VLOOKUP(E33,Parameters!$A$12:$B$14,2,FALSE())) | J33: =IFERROR(IF(VLOOKUP(P33,Fossil_Shares!$J$3:$K$98,2,FALSE())="","EU27 fallback","Eurostat"),"EU27 fallback") | K33: =VLOOKUP(D33,Parameters!$A$18:$B$21,2,FALSE()) | L33: =IF(N33="YES",F33*H33,0) | M33: =L33*I33*K33 | N33: YES | P33: =C33&"|"&E33 | Q33: Recycled containerboard + corrugated; Pulp misc. = recovered-fibre prep (not virgin pulp)
A34: 44375512 | B34: Mercer Rosenthal GmbH - MR - Mercer International Group | C34: Germany | D34: Pulp | E34: C1711 | F34: 164844.5 | G34: PROXY | H34: =VLOOKUP(D34,Parameters!$A$5:$B$8,2,FALSE()) | I34: =IFERROR(IF(VLOOKUP(P34,Fossil_Shares!$J$3:$K$98,2,FALSE())="",VLOOKUP(E34,Parameters!$A$12:$B$14,2,FALSE()),VLOOKUP(P34,Fossil_Shares!$J$3:$K$98,2,FALSE())),VLOOKUP(E34,Parameters!$A$12:$B$14,2,FALSE())) | J34: =IFERROR(IF(VLOOKUP(P34,Fossil_Shares!$J$3:$K$98,2,FALSE())="","EU27 fallback","Eurostat"),"EU27 fallback") | K34: =VLOOKUP(D34,Parameters!$A$18:$B$21,2,FALSE()) | L34: =IF(N34="YES",F34*H34,0) | M34: =L34*I34*K34 | N34: YES | P34: =C34&"|"&E34 | Q34: NBSK market pulp ~360kt/yr + lignin/tall oil; no paper (Mercer Int'l 10-K)
A35: 44375511 | B35: Essity Operations Mannheim GmbH Pulp Mill | C35: Germany | D35: Tissue | E35: C17xP | F35: 164844.5 | G35: PROXY | H35: =VLOOKUP(D35,Parameters!$A$5:$B$8,2,FALSE()) | I35: =IFERROR(IF(VLOOKUP(P35,Fossil_Shares!$J$3:$K$98,2,FALSE())="",VLOOKUP(E35,Parameters!$A$12:$B$14,2,FALSE()),VLOOKUP(P35,Fossil_Shares!$J$3:$K$98,2,FALSE())),VLOOKUP(E35,Parameters!$A$12:$B$14,2,FALSE())) | J35: =IFERROR(IF(VLOOKUP(P35,Fossil_Shares!$J$3:$K$98,2,FALSE())="","EU27 fallback","Eurostat"),"EU27 fallback") | K35: =VLOOKUP(D35,Parameters!$A$18:$B$21,2,FALSE()) | L35: =IF(N35="YES",F35*H35,0) | M35: =L35*I35*K35 | N35: YES | P35: =C35&"|"&E35 | Q35: Largest European tissue plant (283kt/yr) + wheat-straw alt-fibre pulp on-site (Essity press release)
A36: 44375513 | B36: Sappi Stockstadt Mill | C36: Germany | D36: Integrated | E36: C17 | F36: 164844.5 | G36: PROXY | H36: =VLOOKUP(D36,Parameters!$A$5:$B$8,2,FALSE()) | I36: =IFERROR(IF(VLOOKUP(P36,Fossil_Shares!$J$3:$K$98,2,FALSE())="",VLOOKUP(E36,Parameters!$A$12:$B$14,2,FALSE()),VLOOKUP(P36,Fossil_Shares!$J$3:$K$98,2,FALSE())),VLOOKUP(E36,Parameters!$A$12:$B$14,2,FALSE())) | J36: =IFERROR(IF(VLOOKUP(P36,Fossil_Shares!$J$3:$K$98,2,FALSE())="","EU27 fallback","Eurostat"),"EU27 fallback") | K36: =VLOOKUP(D36,Parameters!$A$18:$B$21,2,FALSE()) | L36: =IF(N36="YES",F36*H36,0) | M36: =L36*I36*K36 | N36: no | O36: CLOSED|DUPLICATE | P36: =C36&"|"&E36 | Q36: Duplicate of 44375514 — same integrated Stockstadt mill; CLOSED Q1 2024
A37: 44375514 | B37: Sappi Stockstadt GmbH - Division of Sappi Fine Paper Europe | C37: Germany | D37: Integrated | E37: C17 | F37: 164844.5 | G37: PROXY | H37: =VLOOKUP(D37,Parameters!$A$5:$B$8,2,FALSE()) | I37: =IFERROR(IF(VLOOKUP(P37,Fossil_Shares!$J$3:$K$98,2,FALSE())="",VLOOKUP(E37,Parameters!$A$12:$B$14,2,FALSE()),VLOOKUP(P37,Fossil_Shares!$J$3:$K$98,2,FALSE())),VLOOKUP(E37,Parameters!$A$12:$B$14,2,FALSE())) | J37: =IFERROR(IF(VLOOKUP(P37,Fossil_Shares!$J$3:$K$98,2,FALSE())="","EU27 fallback","Eurostat"),"EU27 fallback") | K37: =VLOOKUP(D37,Parameters!$A$18:$B$21,2,FALSE()) | L37: =IF(N37="YES",F37*H37,0) | M37: =L37*I37*K37 | N37: no | O37: CLOSED | P37: =C37&"|"&E37 | Q37: Integrated 145kt internal pulp + 220kt CWF paper — CLOSED Q1 2024 (Printing Impressions)
A38: 44375505 | B38: ZS Zellstoff Stendal GmbH - Mercer Stendal | C38: Germany | D38: Pulp | E38: C1711 | F38: 275672.16 | G38: ok | H38: =VLOOKUP(D38,Parameters!$A$5:$B$8,2,FALSE()) | I38: =IFERROR(IF(VLOOKUP(P38,Fossil_Shares!$J$3:$K$98,2,FALSE())="",VLOOKUP(E38,Parameters!$A$12:$B$14,2,FALSE()),VLOOKUP(P38,Fossil_Shares!$J$3:$K$98,2,FALSE())),VLOOKUP(E38,Parameters!$A$12:$B$14,2,FALSE())) | J38: =IFERROR(IF(VLOOKUP(P38,Fossil_Shares!$J$3:$K$98,2,FALSE())="","EU27 fallback","Eurostat"),"EU27 fallback") | K38: =VLOOKUP(D38,Parameters!$A$18:$B$21,2,FALSE()) | L38: =IF(N38="YES",F38*H38,0) | M38: =L38*I38*K38 | N38: YES | P38: =C38&"|"&E38 | Q38: Greenfield single-line NBSK market pulp mill 740kt/yr; no paper (Mercer Int'l)
A39: 44375539 | B39: Palm GmbH & Co. KG | C39: Germany | D39: Paper/Board | E39: C17xP | F39: 490081.31 | G39: PROXY | H39: =VLOOKUP(D39,Parameters!$A$5:$B$8,2,FALSE()) | I39: =IFERROR(IF(VLOOKUP(P39,Fossil_Shares!$J$3:$K$98,2,FALSE())="",VLOOKUP(E39,Parameters!$A$12:$B$14,2,FALSE()),VLOOKUP(P39,Fossil_Shares!$J$3:$K$98,2,FALSE())),VLOOKUP(E39,Parameters!$A$12:$B$14,2,FALSE())) | J39: =IFERROR(IF(VLOOKUP(P39,Fossil_Shares!$J$3:$K$98,2,FALSE())="","EU27 fallback","Eurostat"),"EU27 fallback") | K39: =VLOOKUP(D39,Parameters!$A$18:$B$21,2,FALSE()) | L39: =IF(N39="YES",F39*H39,0) | M39: =L39*I39*K39 | N39: YES | O39: COUNTRY_CORRECTED | P39: =C39&"|"&E39 | Q39: COUNTRY CORRECTED to DEU. Palm: recycled newsprint/containerboard; no virgin pulp
A40: 44375558 | B40: Arctic Paper Mochenwangen | C40: Germany | D40: Paper/Board | E40: C17xP | G40: ok | H40: =VLOOKUP(D40,Parameters!$A$5:$B$8,2,FALSE()) | I40: =IFERROR(IF(VLOOKUP(P40,Fossil_Shares!$J$3:$K$98,2,FALSE())="",VLOOKUP(E40,Parameters!$A$12:$B$14,2,FALSE()),VLOOKUP(P40,Fossil_Shares!$J$3:$K$98,2,FALSE())),VLOOKUP(E40,Parameters!$A$12:$B$14,2,FALSE())) | J40: =IFERROR(IF(VLOOKUP(P40,Fossil_Shares!$J$3:$K$98,2,FALSE())="","EU27 fallback","Eurostat"),"EU27 fallback") | K40: =VLOOKUP(D40,Parameters!$A$18:$B$21,2,FALSE()) | L40: =IF(N40="YES",F40*H40,0) | M40: =L40*I40*K40 | N40: no | O40: CLOSED|COUNTRY_CORRECTED | P40: =C40&"|"&E40 | Q40: COUNTRY CORRECTED to DEU (Mochenwangen, Baden-Württemberg). Arctic Paper graphic paper mill — CLOSED 2015
...

Sheet Country_Summary
A1: Country Summary — SUMIFS over kept facilities (live formulas)
A2: Country | B2: Sites (kept) | C2: Output (Mt) | D2: Heat Demand (TWh) | E2: Replaceable (TWh) | F2: Implied Fossil Share | G2: Avg Intensity (MWh/t)
A3: Austria | B3: =COUNTIFS(Facilities!$C$3:$C$90,A3,Facilities!$N$3:$N$90,"YES") | C3: =SUMIFS(Facilities!$F$3:$F$90,Facilities!$C$3:$C$90,A3,Facilities!$N$3:$N$90,"YES")/1000000 | D3: =SUMIFS(Facilities!$L$3:$L$90,Facilities!$C$3:$C$90,A3,Facilities!$N$3:$N$90,"YES")/1000000 | E3: =SUMIFS(Facilities!$M$3:$M$90,Facilities!$C$3:$C$90,A3,Facilities!$N$3:$N$90,"YES")/1000000 | F3: =IF(D3=0,0,E3/D3) | G3: =IF(C3=0,0,D3/C3)
A4: Belgium | B4: =COUNTIFS(Facilities!$C$3:$C$90,A4,Facilities!$N$3:$N$90,"YES") | C4: =SUMIFS(Facilities!$F$3:$F$90,Facilities!$C$3:$C$90,A4,Facilities!$N$3:$N$90,"YES")/1000000 | D4: =SUMIFS(Facilities!$L$3:$L$90,Facilities!$C$3:$C$90,A4,Facilities!$N$3:$N$90,"YES")/1000000 | E4: =SUMIFS(Facilities!$M$3:$M$90,Facilities!$C$3:$C$90,A4,Facilities!$N$3:$N$90,"YES")/1000000 | F4: =IF(D4=0,0,E4/D4) | G4: =IF(C4=0,0,D4/C4)
A5: Bulgaria | B5: =COUNTIFS(Facilities!$C$3:$C$90,A5,Facilities!$N$3:$N$90,"YES") | C5: =SUMIFS(Facilities!$F$3:$F$90,Facilities!$C$3:$C$90,A5,Facilities!$N$3:$N$90,"YES")/1000000 | D5: =SUMIFS(Facilities!$L$3:$L$90,Facilities!$C$3:$C$90,A5,Facilities!$N$3:$N$90,"YES")/1000000 | E5: =SUMIFS(Facilities!$M$3:$M$90,Facilities!$C$3:$C$90,A5,Facilities!$N$3:$N$90,"YES")/1000000 | F5: =IF(D5=0,0,E5/D5) | G5: =IF(C5=0,0,D5/C5)
A6: Czechia | B6: =COUNTIFS(Facilities!$C$3:$C$90,A6,Facilities!$N$3:$N$90,"YES") | C6: =SUMIFS(Facilities!$F$3:$F$90,Facilities!$C$3:$C$90,A6,Facilities!$N$3:$N$90,"YES")/1000000 | D6: =SUMIFS(Facilities!$L$3:$L$90,Facilities!$C$3:$C$90,A6,Facilities!$N$3:$N$90,"YES")/1000000 | E6: =SUMIFS(Facilities!$M$3:$M$90,Facilities!$C$3:$C$90,A6,Facilities!$N$3:$N$90,"YES")/1000000 | F6: =IF(D6=0,0,E6/D6) | G6: =IF(C6=0,0,D6/C6)
A7: France | B7: =COUNTIFS(Facilities!$C$3:$C$90,A7,Facilities!$N$3:$N$90,"YES") | C7: =SUMIFS(Facilities!$F$3:$F$90,Facilities!$C$3:$C$90,A7,Facilities!$N$3:$N$90,"YES")/1000000 | D7: =SUMIFS(Facilities!$L$3:$L$90,Facilities!$C$3:$C$90,A7,Facilities!$N$3:$N$90,"YES")/1000000 | E7: =SUMIFS(Facilities!$M$3:$M$90,Facilities!$C$3:$C$90,A7,Facilities!$N$3:$N$90,"YES")/1000000 | F7: =IF(D7=0,0,E7/D7) | G7: =IF(C7=0,0,D7/C7)
A8: Germany | B8: =COUNTIFS(Facilities!$C$3:$C$90,A8,Facilities!$N$3:$N$90,"YES") | C8: =SUMIFS(Facilities!$F$3:$F$90,Facilities!$C$3:$C$90,A8,Facilities!$N$3:$N$90,"YES")/1000000 | D8: =SUMIFS(Facilities!$L$3:$L$90,Facilities!$C$3:$C$90,A8,Facilities!$N$3:$N$90,"YES")/1000000 | E8: =SUMIFS(Facilities!$M$3:$M$90,Facilities!$C$3:$C$90,A8,Facilities!$N$3:$N$90,"YES")/1000000 | F8: =IF(D8=0,0,E8/D8) | G8: =IF(C8=0,0,D8/C8)
A9: Greece | B9: =COUNTIFS(Facilities!$C$3:$C$90,A9,Facilities!$N$3:$N$90,"YES") | C9: =SUMIFS(Facilities!$F$3:$F$90,Facilities!$C$3:$C$90,A9,Facilities!$N$3:$N$90,"YES")/1000000 | D9: =SUMIFS(Facilities!$L$3:$L$90,Facilities!$C$3:$C$90,A9,Facilities!$N$3:$N$90,"YES")/1000000 | E9: =SUMIFS(Facilities!$M$3:$M$90,Facilities!$C$3:$C$90,A9,Facilities!$N$3:$N$90,"YES")/1000000 | F9: =IF(D9=0,0,E9/D9) | G9: =IF(C9=0,0,D9/C9)
A10: Hungary | B10: =COUNTIFS(Facilities!$C$3:$C$90,A10,Facilities!$N$3:$N$90,"YES") | C10: =SUMIFS(Facilities!$F$3:$F$90,Facilities!$C$3:$C$90,A10,Facilities!$N$3:$N$90,"YES")/1000000 | D10: =SUMIFS(Facilities!$L$3:$L$90,Facilities!$C$3:$C$90,A10,Facilities!$N$3:$N$90,"YES")/1000000 | E10: =SUMIFS(Facilities!$M$3:$M$90,Facilities!$C$3:$C$90,A10,Facilities!$N$3:$N$90,"YES")/1000000 | F10: =IF(D10=0,0,E10/D10) | G10: =IF(C10=0,0,D10/C10)
A11: Italy | B11: =COUNTIFS(Facilities!$C$3:$C$90,A11,Facilities!$N$3:$N$90,"YES") | C11: =SUMIFS(Facilities!$F$3:$F$90,Facilities!$C$3:$C$90,A11,Facilities!$N$3:$N$90,"YES")/1000000 | D11: =SUMIFS(Facilities!$L$3:$L$90,Facilities!$C$3:$C$90,A11,Facilities!$N$3:$N$90,"YES")/1000000 | E11: =SUMIFS(Facilities!$M$3:$M$90,Facilities!$C$3:$C$90,A11,Facilities!$N$3:$N$90,"YES")/1000000 | F11: =IF(D11=0,0,E11/D11) | G11: =IF(C11=0,0,D11/C11)
A12: Netherlands | B12: =COUNTIFS(Facilities!$C$3:$C$90,A12,Facilities!$N$3:$N$90,"YES") | C12: =SUMIFS(Facilities!$F$3:$F$90,Facilities!$C$3:$C$90,A12,Facilities!$N$3:$N$90,"YES")/1000000 | D12: =SUMIFS(Facilities!$L$3:$L$90,Facilities!$C$3:$C$90,A12,Facilities!$N$3:$N$90,"YES")/1000000 | E12: =SUMIFS(Facilities!$M$3:$M$90,Facilities!$C$3:$C$90,A12,Facilities!$N$3:$N$90,"YES")/1000000 | F12: =IF(D12=0,0,E12/D12) | G12: =IF(C12=0,0,D12/C12)
A13: Norway | B13: =COUNTIFS(Facilities!$C$3:$C$90,A13,Facilities!$N$3:$N$90,"YES") | C13: =SUMIFS(Facilities!$F$3:$F$90,Facilities!$C$3:$C$90,A13,Facilities!$N$3:$N$90,"YES")/1000000 | D13: =SUMIFS(Facilities!$L$3:$L$90,Facilities!$C$3:$C$90,A13,Facilities!$N$3:$N$90,"YES")/1000000 | E13: =SUMIFS(Facilities!$M$3:$M$90,Facilities!$C$3:$C$90,A13,Facilities!$N$3:$N$90,"YES")/1000000 | F13: =IF(D13=0,0,E13/D13) | G13: =IF(C13=0,0,D13/C13)
A14: Poland | B14: =COUNTIFS(Facilities!$C$3:$C$90,A14,Facilities!$N$3:$N$90,"YES") | C14: =SUMIFS(Facilities!$F$3:$F$90,Facilities!$C$3:$C$90,A14,Facilities!$N$3:$N$90,"YES")/1000000 | D14: =SUMIFS(Facilities!$L$3:$L$90,Facilities!$C$3:$C$90,A14,Facilities!$N$3:$N$90,"YES")/1000000 | E14: =SUMIFS(Facilities!$M$3:$M$90,Facilities!$C$3:$C$90,A14,Facilities!$N$3:$N$90,"YES")/1000000 | F14: =IF(D14=0,0,E14/D14) | G14: =IF(C14=0,0,D14/C14)
... A20: United Kingdom | B20: =COUNTIFS(Facilities!$C$3:$C$90,A20,Facilities!$N$3:$N$90,"YES") | C20: =SUMIFS(Facilities!$F$3:$F$90,Facilities!$C$3:$C$90,A20,Facilities!$N$3:$N$90,"YES")/1000000 | D20: =SUMIFS(Facilities!$L$3:$L$90,Facilities!$C$3:$C$90,A20,Facilities!$N$3:$N$90,"YES")/1000000 | E20: =SUMIFS(Facilities!$M$3:$M$90,Facilities!$C$3:$C$90,A20,Facilities!$N$3:$N$90,"YES")/1000000 | F20: =IF(D20=0,0,E20/D20) | G20: =IF(C20=0,0,D20/C20)
A21: TOTAL | B21: =SUM(B3:B20) | C21: =SUM(C3:C20) | D21: =SUM(D3:D20) | E21: =SUM(E3:E20) | F21: =IF(D21=0,0,E21/D21) | G21: =IF(C21=0,0,D21/C21)
